def handle_errors(func):
    async def inner(*args, **kwargs):
        context = args[0]
        try:
            await func(*args, **kwargs)

        except NotImplementedError:
            await context.send(f"ðŸš§ðŸš§ This command is still under development!! ðŸš§ðŸš§")
        except Exception as e:
            print(e)
            await context.send(f"An unexpected error occurred : ðŸ‘‡\n {e} ")
    return inner